Workbook

Sheet Compare
B1: Current | C1: Current lag | D1: =Frames!B1 -> /*- | E1: =Frames!C1 -> /*- lag | F1: =Frames!D1 -> various | G1: =Frames!E1 -> various lag | H1: =Frames!F1 -> redo | I1: =Frames!G1 -> redo lag | J1: Comment | K1: Team 123 old | L1: Team 123 old lag
A2: 1 start (snow) | B2: 174 | C2: 12 | D2: =Frames!H2-($B2) -> 0 | E2: =Frames!I2-($C2) -> 0 | F2: =Frames!J2-($B2) -> 0 | G2: =Frames!K2-($C2) -> 0 | H2: =Frames!L2-($B2) -> 0 | I2: =Frames!M2-($C2) -> 0 | K2: =Frames!Q2-($B2) -> 225 | L2: =Frames!R2-($C2) -> 362
A3: 1 end | B3: 1420 | C3: 12 | D3: =Frames!H3-($B3-$B2) -> 815 | E3: =Frames!I3-($C3-$C2) -> 0 | F3: =Frames!J3-($B3-$B2) -> 28 | G3: =Frames!K3-($C3-$C2) -> 0 | H3: =Frames!L3-($B3-$B2) -> 28 | I3: =Frames!M3-($C3-$C2) -> 0 | K3: =Frames!Q3-($B3-$B2) -> -1246 | L3: =Frames!R3-($C3-$C2) -> 0
A4: 2 start (factory 1) | B4: 2537 | C4: 48 | D4: =Frames!H4-($B4-$B3) -> 36 | E4: =Frames!I4-($C4-$C3) -> 0 | F4: =Frames!J4-($B4-$B3) -> -4 | G4: =Frames!K4-($C4-$C3) -> 0 | H4: =Frames!L4-($B4-$B3) -> -4 | I4: =Frames!M4-($C4-$C3) -> 0 | K4: =Frames!Q4-($B4-$B3) -> -1117 | L4: =Frames!R4-($C4-$C3) -> -36
A5: 2 end | B5: 5032 | C5: 48 | D5: =Frames!H5-($B5-$B4) -> 694 | E5: =Frames!I5-($C5-$C4) -> 0 | F5: =Frames!J5-($B5-$B4) -> 0 | G5: =Frames!K5-($C5-$C4) -> 0 | H5: =Frames!L5-($B5-$B4) -> 0 | I5: =Frames!M5-($C5-$C4) -> 0 | K5: =Frames!Q5-($B5-$B4) -> -2495 | L5: =Frames!R5-($C5-$C4) -> 0
A6: 3 start (factory 2) | B6: 5322 | C6: 87 | D6: =Frames!H6-($B6-$B5) -> 0 | E6: =Frames!I6-($C6-$C5) -> 0 | F6: =Frames!J6-($B6-$B5) -> 0 | G6: =Frames!K6-($C6-$C5) -> 0 | H6: =Frames!L6-($B6-$B5) -> 0 | I6: =Frames!M6-($C6-$C5) -> 0 | K6: =Frames!Q6-($B6-$B5) -> -290 | L6: =Frames!R6-($C6-$C5) -> -39
A7: 3 end | B7: 7645 | C7: 87 | D7: =Frames!H7-($B7-$B6) -> 1112 | E7: =Frames!I7-($C7-$C6) -> 0 | F7: =Frames!J7-($B7-$B6) -> 217 | G7: =Frames!K7-($C7-$C6) -> 0 | H7: =Frames!L7-($B7-$B6) -> 0 | I7: =Frames!M7-($C7-$C6) -> 0 | K7: =Frames!Q7-($B7-$B6) -> -2323 | L7: =Frames!R7-($C7-$C6) -> 0
A8: 4 start (sentinel boss) | B8: 7908 | C8: 107 | D8: =Frames!H8-($B8-$B7) -> 0 | E8: =Frames!I8-($C8-$C7) -> 0 | F8: =Frames!J8-($B8-$B7) -> 0 | G8: =Frames!K8-($C8-$C7) -> 0 | H8: =Frames!L8-($B8-$B7) -> 0 | I8: =Frames!M8-($C8-$C7) -> 0 | K8: =Frames!Q8-($B8-$B7) -> -263 | L8: =Frames!R8-($C8-$C7) -> -20
A9: 4 end | B9: 9898 | C9: 107 | D9: =Frames!H9-($B9-$B8) -> 51 | E9: =Frames!I9-($C9-$C8) -> 0 | F9: =Frames!J9-($B9-$B8) -> 0 | G9: =Frames!K9-($C9-$C8) -> 0 | H9: =Frames!L9-($B9-$B8) -> 0 | I9: =Frames!M9-($C9-$C8) -> 0 | K9: =Frames!Q9-($B9-$B8) -> -1990 | L9: =Frames!R9-($C9-$C8) -> 0
A10: 5 start (factory 3) | B10: 10043 | C10: 122 | D10: =Frames!H10-($B10-$B9) -> 0 | E10: =Frames!I10-($C10-$C9) -> 0 | F10: =Frames!J10-($B10-$B9) -> 0 | G10: =Frames!K10-($C10-$C9) -> 0 | H10: =Frames!L10-($B10-$B9) -> 0 | I10: =Frames!M10-($C10-$C9) -> 0 | K10: =Frames!Q10-($B10-$B9) -> -145 | L10: =Frames!R10-($C10-$C9) -> -15
A11: 5 end | B11: 11959 | C11: 122 | D11: =Frames!H11-($B11-$B10) -> 816 | E11: =Frames!I11-($C11-$C10) -> 0 | F11: =Frames!J11-($B11-$B10) -> 0 | G11: =Frames!K11-($C11-$C10) -> 0 | H11: =Frames!L11-($B11-$B10) -> 0 | I11: =Frames!M11-($C11-$C10) -> 0 | K11: =Frames!Q11-($B11-$B10) -> -1916 | L11: =Frames!R11-($C11-$C10) -> 0
A12: 6 start (space base 1) | B12: 12227 | C12: 146 | D12: =Frames!H12-($B12-$B11) -> 1 | E12: =Frames!I12-($C12-$C11) -> 0 | F12: =Frames!J12-($B12-$B11) -> 0 | G12: =Frames!K12-($C12-$C11) -> 0 | H12: =Frames!L12-($B12-$B11) -> 0 | I12: =Frames!M12-($C12-$C11) -> 0 | K12: =Frames!Q12-($B12-$B11) -> -268 | L12: =Frames!R12-($C12-$C11) -> -24
A13: 6 end | B13: 13424 | C13: 147 | D13: =Frames!H13-($B13-$B12) -> 371 | E13: =Frames!I13-($C13-$C12) -> 0 | F13: =Frames!J13-($B13-$B12) -> 0 | G13: =Frames!K13-($C13-$C12) -> 0 | H13: =Frames!L13-($B13-$B12) -> 0 | I13: =Frames!M13-($C13-$C12) -> 0 | K13: =Frames!Q13-($B13-$B12) -> -1197 | L13: =Frames!R13-($C13-$C12) -> -1
A14: 7 start (space base 2) | B14: 13690 | C14: 166 | D14: =Frames!H14-($B14-$B13) -> 0 | E14: =Frames!I14-($C14-$C13) -> 0 | F14: =Frames!J14-($B14-$B13) -> 0 | G14: =Frames!K14-($C14-$C13) -> 0 | H14: =Frames!L14-($B14-$B13) -> 0 | I14: =Frames!M14-($C14-$C13) -> 0 | K14: =Frames!Q14-($B14-$B13) -> -266 | L14: =Frames!R14-($C14-$C13) -> -19
... A20: 10 start (Magneto boss) | B20: 20544 | C20: 223 | D20: =Frames!H20-($B20-$B19) -> -33 | E20: =Frames!I20-($C20-$C19) -> 0 | F20: =Frames!J20-($B20-$B19) -> -261 | G20: =Frames!K20-($C20-$C19) -> -19 | H20: =Frames!L20-($B20-$B19) -> 0 | I20: =Frames!M20-($C20-$C19) -> 0 | K20: =Frames!Q20-($B20-$B19) -> -261 | L20: =Frames!R20-($C20-$C19) -> -19
A21: 10 end | B21: 22059 | C21: 223 | D21: =Frames!H21-($B21-$B20) -> 77 | E21: =Frames!I21-($C21-$C20) -> 0 | F21: =Frames!J21-($B21-$B20) -> -1515 | G21: =Frames!K21-($C21-$C20) -> 0 | H21: =Frames!L21-($B21-$B20) -> 0 | I21: =Frames!M21-($C21-$C20) -> 0
A22: 11 start (pyramid + Tusk) | B22: 22343 | C22: 253 | D22: =Frames!H22-($B22-$B21) -> 0 | E22: =Frames!I22-($C22-$C21) -> 0 | F22: =Frames!J22-($B22-$B21) -> 22083 | G22: =Frames!K22-($C22-$C21) -> -30 | H22: =Frames!L22-($B22-$B21) -> 0 | I22: =Frames!M22-($C22-$C21) -> 0
A23: 11 end | B23: 25324 | C23: 253 | D23: =Frames!H23-($B23-$B22) -> 978 | E23: =Frames!I23-($C23-$C22) -> 0 | F23: =Frames!J23-($B23-$B22) -> 103 | G23: =Frames!K23-($C23-$C22) -> 0 | H23: =Frames!L23-($B23-$B22) -> 31 | I23: =Frames!M23-($C23-$C22) -> 0
A24: 12 start (inside pyramid) | B24: 25582 | C24: 280 | D24: =Frames!H24-($B24-$B23) -> 36 | E24: =Frames!I24-($C24-$C23) -> 0 | F24: =Frames!J24-($B24-$B23) -> 0 | G24: =Frames!K24-($C24-$C23) -> -27 | H24: =Frames!L24-($B24-$B23) -> 0 | I24: =Frames!M24-($C24-$C23) -> 0
A25: 12 end | B25: 29232 | C25: 280 | D25: =Frames!H25-($B25-$B24) -> 1540 | E25: =Frames!I25-($C25-$C24) -> 0 | F25: =Frames!J25-($B25-$B24) -> -2 | G25: =Frames!K25-($C25-$C24) -> 0 | H25: =Frames!L25-($B25-$B24) -> -2 | I25: =Frames!M25-($C25-$C24) -> 0
A26: 13 start (Apocalyse boss) | B26: 29495 | C26: 299 | D26: =Frames!H26-($B26-$B25) -> 3 | E26: =Frames!I26-($C26-$C25) -> 0 | F26: =Frames!J26-($B26-$B25) -> -42 | G26: =Frames!K26-($C26-$C25) -> -19 | H26: =Frames!L26-($B26-$B25) -> -1 | I26: =Frames!M26-($C26-$C25) -> 0
A27: 13 end | B27: 32956 | C27: 299 | D27: =Frames!H27-($B27-$B26) -> 498 | E27: =Frames!I27-($C27-$C26) -> 0 | F27: =Frames!J27-($B27-$B26) -> -752 | G27: =Frames!K27-($C27-$C26) -> 0 | H27: =Frames!L27-($B27-$B26) -> 0 | I27: =Frames!M27-($C27-$C26) -> 0
A28: 14 start (jungle 1) | B28: 33293 | C28: 320 | D28: =Frames!H28-($B28-$B27) -> 5 | E28: =Frames!I28-($C28-$C27) -> 0 | F28: =Frames!J28-($B28-$B27) -> 722 | G28: =Frames!K28-($C28-$C27) -> 299 | H28: =Frames!L28-($B28-$B27) -> 1 | I28: =Frames!M28-($C28-$C27) -> 0
A29: 14 end | B29: 34867 | C29: 322 | D29: =Frames!H29-($B29-$B28) -> 1186 | E29: =Frames!I29-($C29-$C28) -> -2 | F29: =Frames!J29-($B29-$B28) -> 122 | G29: =Frames!K29-($C29-$C28) -> -1 | H29: =Frames!L29-($B29-$B28) -> -1 | I29: =Frames!M29-($C29-$C28) -> 0
A30: 15 start (jungle 2) | B30: 35160 | C30: 346 | D30: =Frames!H30-($B30-$B29) -> 1 | E30: =Frames!I30-($C30-$C29) -> 0 | F30: =Frames!J30-($B30-$B29) -> -123 | G30: =Frames!K30-($C30-$C29) -> 1 | H30: =Frames!L30-($B30-$B29) -> 0 | I30: =Frames!M30-($C30-$C29) -> 0
A31: 15 end | B31: 36102 | C31: 346 | D31: =Frames!H31-($B31-$B30) -> 455 | E31: =Frames!I31-($C31-$C30) -> 0 | F31: =Frames!J31-($B31-$B30) -> 41 | G31: =Frames!K31-($C31-$C30) -> 0 | H31: =Frames!L31-($B31-$B30) -> 0 | I31: =Frames!M31-($C31-$C30) -> 0
A32: 16 start (purple base 1) | B32: 36399 | C32: 416 | D32: =Frames!H32-($B32-$B31) -> 3 | E32: =Frames!I32-($C32-$C31) -> 0 | F32: =Frames!J32-($B32-$B31) -> -36492 | G32: =Frames!K32-($C32-$C31) -> -416 | H32: =Frames!L32-($B32-$B31) -> 0 | I32: =Frames!M32-($C32-$C31) -> 0
... A47: 23 end | B47: 67620 | C47: 800 | D47: =Frames!H47-($B47-$B46) -> 2634 | E47: =Frames!I47-($C47-$C46) -> 0 | F47: =Frames!J47-($B47-$B46) -> -8240 | G47: =Frames!K47-($C47-$C46) -> -1 | H47: =Frames!L47-($B47-$B46) -> -8240 | I47: =Frames!M47-($C47-$C46) -> -1
D48: =Frames!H48-($B48-$B47) -> -18317 | E48: =Frames!I48-($C48-$C47) -> 7 | F48: =Frames!J48-($B48-$B47) -> 67620 | G48: =Frames!K48-($C48-$C47) -> 800
D49: =Frames!H49-($B49-$B48) -> 0 | E49: =Frames!I49-($C49-$C48) -> 0 | F49: =Frames!J49-($B49-$B48) -> 0 | G49: =Frames!K49-($C49-$C48) -> 0
D50: =Frames!H50-($B50-$B49) -> 0 | E50: =Frames!I50-($C50-$C49) -> 0 | F50: =Frames!J50-($B50-$B49) -> 0 | G50: =Frames!K50-($C50-$C49) -> 0
D51: =Frames!H51-($B51-$B50) -> 0 | E51: =Frames!I51-($C51-$C50) -> 0 | F51: =Frames!J51-($B51-$B50) -> 0 | G51: =Frames!K51-($C51-$C50) -> 0
D52: =Frames!H52-($B52-$B51) -> 0 | E52: =Frames!I52-($C52-$C51) -> 0 | F52: =Frames!J52-($B52-$B51) -> 0 | G52: =Frames!K52-($C52-$C51) -> 0
D53: =Frames!H53-($B53-$B52) -> 0 | E53: =Frames!I53-($C53-$C52) -> 0 | F53: =Frames!J53-($B53-$B52) -> 0 | G53: =Frames!K53-($C53-$C52) -> 0
D54: =Frames!H54-($B54-$B53) -> 0 | E54: =Frames!I54-($C54-$C53) -> 0 | F54: =Frames!J54-($B54-$B53) -> 0 | G54: =Frames!K54-($C54-$C53) -> 0
D55: =Frames!H55-($B55-$B54) -> 0 | E55: =Frames!I55-($C55-$C54) -> 0 | F55: =Frames!J55-($B55-$B54) -> 0 | G55: =Frames!K55-($C55-$C54) -> 0
D56: =Frames!H56-($B56-$B55) -> 0 | E56: =Frames!I56-($C56-$C55) -> 0 | F56: =Frames!J56-($B56-$B55) -> 0 | G56: =Frames!K56-($C56-$C55) -> 0
D57: =Frames!H57-($B57-$B56) -> 0 | E57: =Frames!I57-($C57-$C56) -> 0 | F57: =Frames!J57-($B57-$B56) -> 0 | G57: =Frames!K57-($C57-$C56) -> 0
D58: =Frames!H58-($B58-$B57) -> 0 | E58: =Frames!I58-($C58-$C57) -> 0 | F58: =Frames!J58-($B58-$B57) -> 0 | G58: =Frames!K58-($C58-$C57) -> 0
D59: =Frames!H59-($B59-$B58) -> 0 | E59: =Frames!I59-($C59-$C58) -> 0 | F59: =Frames!J59-($B59-$B58) -> 0 | G59: =Frames!K59-($C59-$C58) -> 0
...

Sheet Frames
A1: Measuring point | B1: /*- | C1: /*- lag | D1: various | E1: various lag | F1: redo | G1: redo lag | H1: Sec 1 | I1: Sec 1 lag | J1: Sec 2 | K1: Sec 2 lag | L1: Sec 3 | M1: Sec 3 lag | O1: pre-redo | P1: p-rd lag | Q1: sec | R1: sec lag
A2: 1 start (snow) | B2: 174 | C2: 12 | D2: 174 | E2: 12 | F2: 174 | G2: 12 | H2: =B2 -> 174 | I2: =C2 -> 12 | J2: =D2 -> 174 | K2: =E2 -> 12 | L2: =F2 -> 174 | M2: =G2 -> 12 | N2: This sheet is static. Don't change anything. | Q2: 399 | R2: 374
A3: 1 end | B3: 2235 | C3: 12 | D3: 1448 | E3: 12 | F3: 1448 | G3: 12 | H3: =B3-B2 -> 2061 | I3: =C3-C2 -> 0 | J3: =D3-D2 -> 1274 | K3: =E3-E2 -> 0 | L3: =F3-F2 -> 1274 | M3: =G3-G2 -> 0 | N3: Stage Start = The first frame that isnt pitch black. | Q3: =O3-O2 -> 0 | R3: =P3-P2 -> 0
A4: 2 start (factory 1) | B4: 3388 | C4: 48 | D4: 2561 | E4: 48 | F4: 2561 | G4: 48 | H4: =B4-B3 -> 1153 | I4: =C4-C3 -> 36 | J4: =D4-D3 -> 1113 | K4: =E4-E3 -> 36 | L4: =F4-F3 -> 1113 | M4: =G4-G3 -> 36 | N4: Stage End = The first frame that IS pitch black when the screen fades out. | Q4: =O4-O3 -> 0 | R4: =P4-P3 -> 0
A5: 2 end | B5: 6577 | C5: 48 | D5: 5056 | E5: 48 | F5: 5056 | G5: 48 | H5: =B5-B4 -> 3189 | I5: =C5-C4 -> 0 | J5: =D5-D4 -> 2495 | K5: =E5-E4 -> 0 | L5: =F5-F4 -> 2495 | M5: =G5-G4 -> 0 | Q5: =O5-O4 -> 0 | R5: =P5-P4 -> 0
A6: 3 start (factory 2) | B6: 6867 | C6: 87 | D6: 5346 | E6: 87 | F6: 5346 | G6: 87 | H6: =B6-B5 -> 290 | I6: =C6-C5 -> 39 | J6: =D6-D5 -> 290 | K6: =E6-E5 -> 39 | L6: =F6-F5 -> 290 | M6: =G6-G5 -> 39 | Q6: =O6-O5 -> 0 | R6: =P6-P5 -> 0
A7: 3 end | B7: 10302 | C7: 87 | D7: 7886 | E7: 87 | F7: 7669 | G7: 87 | H7: =B7-B6 -> 3435 | I7: =C7-C6 -> 0 | J7: =D7-D6 -> 2540 | K7: =E7-E6 -> 0 | L7: =F7-F6 -> 2323 | M7: =G7-G6 -> 0 | Q7: =O7-O6 -> 0 | R7: =P7-P6 -> 0
A8: 4 start (sentinel boss) | B8: 10565 | C8: 107 | D8: 8149 | E8: 107 | F8: 7932 | G8: 107 | H8: =B8-B7 -> 263 | I8: =C8-C7 -> 20 | J8: =D8-D7 -> 263 | K8: =E8-E7 -> 20 | L8: =F8-F7 -> 263 | M8: =G8-G7 -> 20 | Q8: =O8-O7 -> 0 | R8: =P8-P7 -> 0
A9: 4 end | B9: 12606 | C9: 107 | D9: 10139 | E9: 107 | F9: 9922 | G9: 107 | H9: =B9-B8 -> 2041 | I9: =C9-C8 -> 0 | J9: =D9-D8 -> 1990 | K9: =E9-E8 -> 0 | L9: =F9-F8 -> 1990 | M9: =G9-G8 -> 0 | Q9: =O9-O8 -> 0 | R9: =P9-P8 -> 0
A10: 5 start (factory 3) | B10: 12751 | C10: 122 | D10: 10284 | E10: 122 | F10: 10067 | G10: 122 | H10: =B10-B9 -> 145 | I10: =C10-C9 -> 15 | J10: =D10-D9 -> 145 | K10: =E10-E9 -> 15 | L10: =F10-F9 -> 145 | M10: =G10-G9 -> 15 | Q10: =O10-O9 -> 0 | R10: =P10-P9 -> 0
A11: 5 end | B11: 15483 | C11: 122 | D11: 12200 | E11: 122 | F11: 11983 | G11: 122 | H11: =B11-B10 -> 2732 | I11: =C11-C10 -> 0 | J11: =D11-D10 -> 1916 | K11: =E11-E10 -> 0 | L11: =F11-F10 -> 1916 | M11: =G11-G10 -> 0 | Q11: =O11-O10 -> 0 | R11: =P11-P10 -> 0
A12: 6 start (space base 1) | B12: 15752 | C12: 146 | D12: 12468 | E12: 146 | F12: 12251 | G12: 146 | H12: =B12-B11 -> 269 | I12: =C12-C11 -> 24 | J12: =D12-D11 -> 268 | K12: =E12-E11 -> 24 | L12: =F12-F11 -> 268 | M12: =G12-G11 -> 24 | Q12: =O12-O11 -> 0 | R12: =P12-P11 -> 0
A13: 6 end | B13: 17320 | C13: 147 | D13: 13665 | E13: 147 | F13: 13448 | G13: 147 | H13: =B13-B12 -> 1568 | I13: =C13-C12 -> 1 | J13: =D13-D12 -> 1197 | K13: =E13-E12 -> 1 | L13: =F13-F12 -> 1197 | M13: =G13-G12 -> 1 | Q13: =O13-O12 -> 0 | R13: =P13-P12 -> 0
A14: 7 start (space base 2) | B14: 17586 | C14: 166 | D14: 13931 | E14: 166 | F14: 13714 | G14: 166 | H14: =B14-B13 -> 266 | I14: =C14-C13 -> 19 | J14: =D14-D13 -> 266 | K14: =E14-E13 -> 19 | L14: =F14-F13 -> 266 | M14: =G14-G13 -> 19 | Q14: =O14-O13 -> 0 | R14: =P14-P13 -> 0
A15: 7 end | B15: 20643 | C15: 166 | D15: 16136 | E15: 166 | F15: 15873 | G15: 166 | H15: =B15-B14 -> 3057 | I15: =C15-C14 -> 0 | J15: =D15-D14 -> 2205 | K15: =E15-E14 -> 0 | L15: =F15-F14 -> 2159 | M15: =G15-G14 -> 0 | Q15: =O15-O14 -> 0 | R15: =P15-P14 -> 0
A16: 8 start (falling level) | B16: 20880 | C16: 184 | D16: 16373 | E16: 185 | F16: 16110 | G16: 185 | H16: =B16-B15 -> 237 | I16: =C16-C15 -> 18 | J16: =D16-D15 -> 237 | K16: =E16-E15 -> 19 | L16: =F16-F15 -> 237 | M16: =G16-G15 -> 19 | Q16: =O16-O15 -> 0 | R16: =P16-P15 -> 0
A17: 8 end | B17: 24090 | C17: 184 | F17: 18911 | G17: 185 | H17: =B17-B16 -> 3210 | I17: =C17-C16 -> 0 | J17: =D17-D16 -> -16373 | K17: =E17-E16 -> -185 | L17: =F17-F16 -> 2801 | M17: =G17-G16 -> 0 | Q17: =O17-O16 -> 0 | R17: =P17-P16 -> 0
A18: 9 start (Exodus boss) | B18: 24409 | C18: 203 | F18: 19227 | G18: 204 | H18: =B18-B17 -> 319 | I18: =C18-C17 -> 19 | J18: =D18-D17 -> 0 | K18: =E18-E17 -> 0 | L18: =F18-F17 -> 316 | M18: =G18-G17 -> 19 | Q18: =O18-O17 -> 0 | R18: =P18-P17 -> 0
A19: 9 end | B19: 25489 | C19: 203 | F19: 20307 | G19: 204 | H19: =B19-B18 -> 1080 | I19: =C19-C18 -> 0 | J19: =D19-D18 -> 0 | K19: =E19-E18 -> 0 | L19: =F19-F18 -> 1080 | M19: =G19-G18 -> 0 | Q19: =O19-O18 -> 0 | R19: =P19-P18 -> 0
A20: 10 start (Magneto boss) | B20: 25717 | C20: 222 | F20: 20568 | G20: 223 | H20: =B20-B19 -> 228 | I20: =C20-C19 -> 19 | J20: =D20-D19 -> 0 | K20: =E20-E19 -> 0 | L20: =F20-F19 -> 261 | M20: =G20-G19 -> 19 | Q20: =O20-O19 -> 0 | R20: =P20-P19 -> 0
A21: 10 end | B21: 27309 | C21: 222 | F21: 22083 | G21: 223 | H21: =B21-B20 -> 1592 | I21: =C21-C20 -> 0 | J21: =D21-D20 -> 0 | K21: =E21-E20 -> 0 | L21: =F21-F20 -> 1515 | M21: =G21-G20 -> 0
A22: 11 start (pyramid + Tusk) | B22: 27593 | C22: 252 | D22: 22367 | F22: 22367 | G22: 253 | H22: =B22-B21 -> 284 | I22: =C22-C21 -> 30 | J22: =D22-D21 -> 22367 | K22: =E22-E21 -> 0 | L22: =F22-F21 -> 284 | M22: =G22-G21 -> 30
A23: 11 end | B23: 31552 | C23: 252 | D23: 25451 | F23: 25379 | G23: 253 | H23: =B23-B22 -> 3959 | I23: =C23-C22 -> 0 | J23: =D23-D22 -> 3084 | K23: =E23-E22 -> 0 | L23: =F23-F22 -> 3012 | M23: =G23-G22 -> 0
A24: 12 start (inside pyramid) | B24: 31846 | C24: 279 | D24: 25709 | F24: 25637 | G24: 280 | H24: =B24-B23 -> 294 | I24: =C24-C23 -> 27 | J24: =D24-D23 -> 258 | K24: =E24-E23 -> 0 | L24: =F24-F23 -> 258 | M24: =G24-G23 -> 27
A25: 12 end | B25: 37036 | C25: 279 | D25: 29357 | F25: 29285 | G25: 280 | H25: =B25-B24 -> 5190 | I25: =C25-C24 -> 0 | J25: =D25-D24 -> 3648 | K25: =E25-E24 -> 0 | L25: =F25-F24 -> 3648 | M25: =G25-G24 -> 0
A26: 13 start (Apocalyse boss) | B26: 37302 | C26: 298 | D26: 29578 | F26: 29547 | G26: 299 | H26: =B26-B25 -> 266 | I26: =C26-C25 -> 19 | J26: =D26-D25 -> 221 | K26: =E26-E25 -> 0 | L26: =F26-F25 -> 262 | M26: =G26-G25 -> 19
A27: 13 end | B27: 41261 | C27: 298 | D27: 32287 | F27: 33008 | G27: 299 | H27: =B27-B26 -> 3959 | I27: =C27-C26 -> 0 | J27: =D27-D26 -> 2709 | K27: =E27-E26 -> 0 | L27: =F27-F26 -> 3461 | M27: =G27-G26 -> 0
A28: 14 start (jungle 1) | B28: 41603 | C28: 319 | D28: 33346 | E28: 320 | F28: 33346 | G28: 320 | H28: =B28-B27 -> 342 | I28: =C28-C27 -> 21 | J28: =D28-D27 -> 1059 | K28: =E28-E27 -> 320 | L28: =F28-F27 -> 338 | M28: =G28-G27 -> 21
A29: 14 end | B29: 44363 | C29: 319 | D29: 35042 | E29: 321 | F29: 34919 | G29: 322 | H29: =B29-B28 -> 2760 | I29: =C29-C28 -> 0 | J29: =D29-D28 -> 1696 | K29: =E29-E28 -> 1 | L29: =F29-F28 -> 1573 | M29: =G29-G28 -> 2
A30: 15 start (jungle 2) | B30: 44657 | C30: 343 | D30: 35212 | E30: 346 | F30: 35212 | G30: 346 | H30: =B30-B29 -> 294 | I30: =C30-C29 -> 24 | J30: =D30-D29 -> 170 | K30: =E30-E29 -> 25 | L30: =F30-F29 -> 293 | M30: =G30-G29 -> 24
A31: 15 end | B31: 46054 | C31: 343 | D31: 36195 | E31: 346 | F31: 36154 | G31: 346 | H31: =B31-B30 -> 1397 | I31: =C31-C30 -> 0 | J31: =D31-D30 -> 983 | K31: =E31-E30 -> 0 | L31: =F31-F30 -> 942 | M31: =G31-G30 -> 0
A32: 16 start (purple base 1) | B32: 46354 | C32: 413 | F32: 36451 | G32: 416 | H32: =B32-B31 -> 300 | I32: =C32-C31 -> 70 | J32: =D32-D31 -> -36195 | K32: =E32-E31 -> -346 | L32: =F32-F31 -> 297 | M32: =G32-G31 -> 70
A33: 16 end | B33: 48413 | C33: 413 | F33: 37705 | G33: 416 | H33: =B33-B32 -> 2059 | I33: =C33-C32 -> 0 | J33: =D33-D32 -> 0 | K33: =E33-E32 -> 0 | L33: =F33-F32 -> 1254 | M33: =G33-G32 -> 0
A34: 17 start (purple base 2) | B34: 48720 | C34: 496 | D34: 38008 | E34: 499 | F34: 38008 | G34: 499 | H34: =B34-B33 -> 307 | I34: =C34-C33 -> 83 | J34: =D34-D33 -> 38008 | K34: =E34-E33 -> 499 | L34: =F34-F33 -> 303 | M34: =G34-G33 -> 83
A35: 17 end | B35: 50310 | C35: 496 | D35: 39045 | E35: 499 | F35: 39005 | G35: 499 | H35: =B35-B34 -> 1590 | I35: =C35-C34 -> 0 | J35: =D35-D34 -> 1037 | K35: =E35-E34 -> 0 | L35: =F35-F34 -> 997 | M35: =G35-G34 -> 0
A36: 18 start (transformer boss) | B36: 50579 | C36: 518 | D36: 39311 | E36: 521 | F36: 39271 | G36: 521 | H36: =B36-B35 -> 269 | I36: =C36-C35 -> 22 | J36: =D36-D35 -> 266 | K36: =E36-E35 -> 22 | L36: =F36-F35 -> 266 | M36: =G36-G35 -> 22
A37: 18 end | B37: 52068 | C37: 518 | D37: 40674 | E37: 521 | F37: 40500 | G37: 521 | H37: =B37-B36 -> 1489 | I37: =C37-C36 -> 0 | J37: =D37-D36 -> 1363 | K37: =E37-E36 -> 0 | L37: =F37-F36 -> 1229 | M37: =G37-G36 -> 0
A38: 19 start (yellow base) | B38: 52468 | C38: 583 | D38: 40908 | F38: 40908 | G38: 586 | H38: =B38-B37 -> 400 | I38: =C38-C37 -> 65 | J38: =D38-D37 -> 234 | K38: =E38-E37 -> -521 | L38: =F38-F37 -> 408 | M38: =G38-G37 -> 65
A39: 19 end | B39: 56345 | C39: 583 | D39: 43213 | F39: 43036 | G39: 586 | H39: =B39-B38 -> 3877 | I39: =C39-C38 -> 0 | J39: =D39-D38 -> 2305 | K39: =E39-E38 -> 0 | L39: =F39-F38 -> 2128 | M39: =G39-G38 -> 0
A40: 20 start (elevator + Deathbird) | B40: 56573 | C40: 602 | H40: =B40-B39 -> 228 | I40: =C40-C39 -> 19 | J40: =D40-D39 -> -43213 | K40: =E40-E39 -> 0 | L40: =F40-F39 -> -43036 | M40: =G40-G39 -> -586
...

Sheet Glitches
A1: Glitches | B1: useful (where) | C1: useful (where) | D1: useful (where) | E1: useful (where) | F1: useful (where)
A2: Stomps and downward attacks have high acceleration but lower max speed. Stop the stomp and fall normally after you reach the stomp speed cap.
A4: Nightcrawlers jump kick.

Sheet Data
A1: Data (weapon damages, travel speeds)
A2: Attack | B2: Damage | E2: Notes
A3: Beast
A4: Ground pound | B4: 8
A5: Ground pound projectile (yellow health) | B5: 2
A6: All other attacks | B6: 4
A8: Nightcrawler
A9: Teleport with yellow health | B9: 4 | C9: can hit twice | E9: Regardless of charged/uncharged, charge only determines length traveled.
A10: Teleport without yellow health | B10: 1 | C10: can hit twice | E10: Regardless of charged/uncharged, charge only determines length traveled.
A11: All other attacks | B11: 2
A13: Wolverine
A14: Lunge with yellow health | B14: 8
A15: All other attacks | B15: 2
A17: Cyclops/Gambit
A18: Charged laser/card with yellow health | B18: 4
A19: Uncharged laser/card with yellow health | B19: 2
A20: Charged laser/card without yellow health | B20: 2
A21: Uncharged laser/card without yellow health | B21: 1
A22: All other attacks | B22: 2
A24: Psylocke
A25: Energy punch with yellow health | B25: '4 | C25: can hit twice | E25: Second hit depends on enemy invulnerability length
A26: Energy punch without yellow health | B26: '2 | C26: can hit twice | E26: Second hit depends on enemy invulnerability length
A27: All other attacks | B27: 2 | E27: A-punch only hits biological enemies.
A29: Magneto
A30: Energy ball with yellow health | B30: 4
A31: Energy ball without yellow health | B31: 2
A32: Small shots | B32: 1
A36: Horizontal movement | B36: Speed | C36: Acceleration | D36: Deceleration
A37: General
A38: acceleration on ground | B38: '0:80
A40: Beast
A41: max speed on ground | B41: '3:132
A42: max speed in air | B42: '2:226
A43: acceleration in air | B43: instant?
A44: roll move | B44: '6:0
A46: Nightcrawler
A47: max speed on ground | B47: '4:20
A48: max speed in air | B48: '2:156
A49: max speed in somersault | B49: '6:0
A50: acceleration in air | B50: '0:128
...

Sheet Cheats

Sheet Scratchpad
C2: old | D2: diff | E2: new | F2: diff | G2: imp | H2: x
B3: start | C3: 22367 | E3: 22367
B4: ledge 1, R | C4: 22773 | D4: =C4-C3 -> 406 | E4: 22759 | F4: =E4-E3 -> 392 | G4: =D4-F4 -> 14 | H4: >3166
B5: ledge 2, L | C5: 23146 | D5: =C5-C4 -> 373 | E5: 23127 | F5: =E5-E4 -> 368 | G5: =D5-F5 -> 5 | H5: <583
B6: ledge 3, R | C6: 23491 | D6: =C6-C5 -> 345 | E6: 23459 | F6: =E6-E5 -> 332 | G6: =D6-F6 -> 13 | H6: >2800 | P6: || | Q6: Character | R6: || | S6: Jump initial speed | T6: || | U6: Gravity | V6: || | W6: Max downspeed
B7: ledge 4, L | C7: 23803 | D7: =C7-C6 -> 312 | E7: 23754 | F7: =E7-E6 -> 295 | G7: =D7-F7 -> 17 | P7: | | Q7: Beast | R7: | | S7: '8:252 | T7: | | U7: '0:81 | V7: | | W7: '16:0
B8: ledge 5, R | C8: 24072 | D8: =C8-C7 -> 269 | E8: 24014 | F8: =E8-E7 -> 260 | G8: =D8-F8 -> 9 | P8: | | Q8: Nightcrawler | R8: | | S8: '8:224 | T8: | | U8: '0:81 | V8: | | W8: '18:0
B9: upper ledge | C9: 24203 | D9: =C9-C8 -> 131 | E9: 24149 | F9: =E9-E8 -> 135 | G9: =D9-F9 -> -4 | P9: | | Q9: Psylocke | R9: | | S9: '8:184 | T9: | | U9: '0:81 | V9: | | W9: '16:0
B10: ledge 7, R | C10: 24253 | D10: =C10-C9 -> 50 | E10: 24192 | F10: =E10-E9 -> 43 | G10: =D10-F10 -> 7 | P10: | | Q10: Wolverine | R10: | | S10: '7:180 | T10: | | U10: '0:70 | V10: | | W10: '16:0
B11: upper ledge 2 | C11: 24366 | D11: =C11-C10 -> 113 | E11: 24303 | F11: =E11-E10 -> 111 | G11: =D11-F11 -> 2 | P11: | | Q11: Gambit | R11: | | S11: '7:159 | T11: | | U11: '0:70 | V11: | | W11: '16:0
B12: ledge 9, R | C12: 24390 | D12: =C12-C11 -> 24 | E12: 24327 | F12: =E12-E11 -> 24 | G12: =D12-F12 -> 0 | P12: | | Q12: Cyclops | R12: | | S12: '7:156 | T12: | | U12: '0:70 | V12: | | W12: '16:0
B13: ledge under boss | C13: 24410 | D13: =C13-C12 -> 20 | E13: 24343 | F13: =E13-E12 -> 16 | G13: =D13-F13 -> 4 | P13: | | Q13: Magneto | R13: | | S13: '6:196 | T13: | | U13: '0:35 | V13: | | W13: '16:0
B14: boss hp decrease | C14: 24431 | D14: =C14-C13 -> 21 | E14: 24365 | F14: =E14-E13 -> 22 | G14: =D14-F14 -> -1
B15: 28 | E15: 24365 | F15: =E15-E14 -> 0
B16: 24 | E16: 24477 | F16: =E16-E15 -> 112 | M16: 217
B17: 20 | E17: 24589 | F17: =E17-E16 -> 112 | M17: 70
B18: 16 | E18: 24701 | F18: =E18-E17 -> 112 | M18: 242
B19: 12 | E19: 24813 | F19: =E19-E18 -> 112 | M19: 334
B20: 8 | E20: 24925 | F20: =E20-E19 -> 112
B21: 4 | E21: 25037 | F21: =E21-E20 -> 112
B22: 0 | E22: 25149 | F22: =E22-E21 -> 112 | M22: 615
M23: 341 | P23: || | Q23: Beast | R23: || | S23: Max speed | T23: || | U23: Acceleration
C24: old | D24: new | M24: 334 | P24: | | Q24: Stomp | R24: | | S24: '8:96 | T24: | | U24: '0:180
B25: gambit | C25: 66089 | D25: 65740 | E25: =C25-D25 -> 349 | P25: || | Q25: Nightcrawler | R25: || | S25: Max speed | T25: || | U25: Acceleration
C26: 66120 | D26: 65771 | E26: =C26-D26 -> 349 | P26: | | Q26: Stomp | R26: | | S26: '8:96 | T26: | | U26: '0:180
C27: 66162 | D27: 65813 | E27: =C27-D27 -> 349 | M27: 248 | P27: | | Q27: Diagonal kick | R27: | | S27: '8:96 | T27: | | U27: '0:180
C28: 66193 | D28: 65844 | E28: =C28-D28 -> 349 | M28: 330 | P28: | | Q28: Quick drop | R28: | | S28: '18:0 | T28: | | U28: '1:94
C29: 66242 | D29: 65890 | E29: =C29-D29 -> 352 | M29: 341 | P29: || | Q29: Wolverine | R29: || | S29: Max speed | T29: || | U29: Acceleration
C30: 66567 | D30: 66206 | E30: =C30-D30 -> 361 | M30: 334 | P30: | | Q30: Downwards attack | R30: | | S30: '8:96 | T30: | | U30: '0:180
M31: 341 | P31: | | Q31: Quick drop | R31: | | S31: '16:0 | T31: | | U31: '1:144
B32: hit 1 | C32: 67000 | D32: 66634 | M32: 334
B33: hit 2 | C33: 67032 | D33: 66665 | E33: =C33-C32 -> 32 | F33: =D33-D32 -> 31 | M33: =sum(M16:M32) -> 4081
B34: hit 3 | C34: 67077 | D34: 66710 | E34: =C34-C33 -> 45 | F34: =D34-D33 -> 45
B35: hit 4 | C35: 67109 | D35: 66742 | E35: =C35-C34 -> 32 | F35: =D35-D34 -> 32
B36: morph start | C36: 67149 | D36: 66780 | E36: =C36-C35 -> 40 | F36: =D36-D35 -> 38
B37: hit 1 | C37: 67990 | D37: 67537 | G37: 67537
B38: hit 2 | C38: 68040 | D38: 67574 | E38: =C38-C37 -> 50 | F38: =D38-D37 -> 37 | G38: 67573
B39: hit 3 | C39: 68070 | D39: 67604 | E39: =C39-C38 -> 30 | F39: =D39-D38 -> 30
B40: hit 4 | C40: 68101 | D40: 67635 | E40: =C40-C39 -> 31 | F40: =D40-D39 -> 31
B41: morph start | C41: 68144 | D41: 67678 | E41: =C41-C40 -> 43 | F41: =D41-D40 -> 43
...
